2024-11-19 22:01:09 INFO Retry attempt failed:
Traceback (most recent call last):
  File "/home/yhlong/anaconda3/envs/surrol_datagen_test/lib/python3.7/site-packages/urllib3/connection.py", line 207, in _new_conn
    socket_options=self.socket_options,
  File "/home/yhlong/anaconda3/envs/surrol_datagen_test/lib/python3.7/site-packages/urllib3/util/connection.py", line 85, in create_connection
    raise err
  File "/home/yhlong/anaconda3/envs/surrol_datagen_test/lib/python3.7/site-packages/urllib3/util/connection.py", line 73, in create_connection
    sock.connect(sa)
ConnectionRefusedError: [Errno 111] Connection refused

The above exception was the direct cause of the following exception:

Traceback (most recent call last):
  File "/home/yhlong/anaconda3/envs/surrol_datagen_test/lib/python3.7/site-packages/urllib3/connectionpool.py", line 803, in urlopen
    **response_kw,
  File "/home/yhlong/anaconda3/envs/surrol_datagen_test/lib/python3.7/site-packages/urllib3/connectionpool.py", line 505, in _make_request
    enforce_content_length=enforce_content_length,
  File "/home/yhlong/anaconda3/envs/surrol_datagen_test/lib/python3.7/site-packages/urllib3/connection.py", line 395, in request
    self.endheaders()
  File "/home/yhlong/anaconda3/envs/surrol_datagen_test/lib/python3.7/http/client.py", line 1276, in endheaders
    self._send_output(message_body, encode_chunked=encode_chunked)
  File "/home/yhlong/anaconda3/envs/surrol_datagen_test/lib/python3.7/http/client.py", line 1036, in _send_output
    self.send(msg)
  File "/home/yhlong/anaconda3/envs/surrol_datagen_test/lib/python3.7/http/client.py", line 976, in send
    self.connect()
  File "/home/yhlong/anaconda3/envs/surrol_datagen_test/lib/python3.7/site-packages/urllib3/connection.py", line 243, in connect
    self.sock = self._new_conn()
  File "/home/yhlong/anaconda3/envs/surrol_datagen_test/lib/python3.7/site-packages/urllib3/connection.py", line 220, in _new_conn
    ) from e
urllib3.exceptions.NewConnectionError: <urllib3.connection.HTTPConnection object at 0x7fea2f9b56d0>: Failed to establish a new connection: [Errno 111] Connection refused

The above exception was the direct cause of the following exception:

Traceback (most recent call last):
  File "/home/yhlong/anaconda3/envs/surrol_datagen_test/lib/python3.7/site-packages/requests/adapters.py", line 497, in send
    chunked=chunked,
  File "/home/yhlong/anaconda3/envs/surrol_datagen_test/lib/python3.7/site-packages/urllib3/connectionpool.py", line 846, in urlopen
    method, url, error=new_e, _pool=self, _stacktrace=sys.exc_info()[2]
  File "/home/yhlong/anaconda3/envs/surrol_datagen_test/lib/python3.7/site-packages/urllib3/util/retry.py", line 515, in increment
    raise MaxRetryError(_pool, url, reason) from reason  # type: ignore[arg-type]
urllib3.exceptions.MaxRetryError: HTTPConnectionPool(host='localhost', port=8080): Max retries exceeded with url: /graphql (Caused by NewConnectionError('<urllib3.connection.HTTPConnection object at 0x7fea2f9b56d0>: Failed to establish a new connection: [Errno 111] Connection refused'))

During handling of the above exception, another exception occurred:

Traceback (most recent call last):
  File "/home/yhlong/anaconda3/envs/surrol_datagen_test/lib/python3.7/site-packages/wandb/sdk/lib/retry.py", line 131, in __call__
    result = self._call_fn(*args, **kwargs)
  File "/home/yhlong/anaconda3/envs/surrol_datagen_test/lib/python3.7/site-packages/wandb/sdk/internal/internal_api.py", line 340, in execute
    return self.client.execute(*args, **kwargs)  # type: ignore
  File "/home/yhlong/anaconda3/envs/surrol_datagen_test/lib/python3.7/site-packages/wandb/vendor/gql-0.2.0/wandb_gql/client.py", line 52, in execute
    result = self._get_result(document, *args, **kwargs)
  File "/home/yhlong/anaconda3/envs/surrol_datagen_test/lib/python3.7/site-packages/wandb/vendor/gql-0.2.0/wandb_gql/client.py", line 60, in _get_result
    return self.transport.execute(document, *args, **kwargs)
  File "/home/yhlong/anaconda3/envs/surrol_datagen_test/lib/python3.7/site-packages/wandb/sdk/lib/gql_request.py", line 58, in execute
    request = self.session.post(self.url, **post_args)
  File "/home/yhlong/anaconda3/envs/surrol_datagen_test/lib/python3.7/site-packages/requests/sessions.py", line 637, in post
    return self.request("POST", url, data=data, json=json, **kwargs)
  File "/home/yhlong/anaconda3/envs/surrol_datagen_test/lib/python3.7/site-packages/requests/sessions.py", line 589, in request
    resp = self.send(prep, **send_kwargs)
  File "/home/yhlong/anaconda3/envs/surrol_datagen_test/lib/python3.7/site-packages/requests/sessions.py", line 703, in send
    r = adapter.send(request, **kwargs)
  File "/home/yhlong/anaconda3/envs/surrol_datagen_test/lib/python3.7/site-packages/requests/adapters.py", line 519, in send
    raise ConnectionError(e, request=request)
requests.exceptions.ConnectionError: HTTPConnectionPool(host='localhost', port=8080): Max retries exceeded with url: /graphql (Caused by NewConnectionError('<urllib3.connection.HTTPConnection object at 0x7fea2f9b56d0>: Failed to establish a new connection: [Errno 111] Connection refused'))
